Traceback (most recent call last):
  File "/home/takezawa/anaconda3/envs/MT_env/lib/python3.8/urllib/request.py", line 1354, in do_open
    h.request(req.get_method(), req.selector, req.data, headers,
  File "/home/takezawa/anaconda3/envs/MT_env/lib/python3.8/http/client.py", line 1256, in request
    self._send_request(method, url, body, headers, encode_chunked)
  File "/home/takezawa/anaconda3/envs/MT_env/lib/python3.8/http/client.py", line 1302, in _send_request
    self.endheaders(body, encode_chunked=encode_chunked)
  File "/home/takezawa/anaconda3/envs/MT_env/lib/python3.8/http/client.py", line 1251, in endheaders
    self._send_output(message_body, encode_chunked=encode_chunked)
  File "/home/takezawa/anaconda3/envs/MT_env/lib/python3.8/http/client.py", line 1011, in _send_output
    self.send(msg)
  File "/home/takezawa/anaconda3/envs/MT_env/lib/python3.8/http/client.py", line 951, in send
    self.connect()
  File "/home/takezawa/anaconda3/envs/MT_env/lib/python3.8/http/client.py", line 1418, in connect
    super().connect()
  File "/home/takezawa/anaconda3/envs/MT_env/lib/python3.8/http/client.py", line 922, in connect
    self.sock = self._create_connection(
  File "/home/takezawa/anaconda3/envs/MT_env/lib/python3.8/socket.py", line 808, in create_connection
    raise err
  File "/home/takezawa/anaconda3/envs/MT_env/lib/python3.8/socket.py", line 796, in create_connection
    sock.connect(sa)
OSError: [Errno 101] Network is unreachable

During handling of the above exception, another exception occurred:

Traceback (most recent call last):
  File "main_vit.py", line 45, in <module>
    trainset = torchvision.datasets.CIFAR10(
  File "/home/takezawa/anaconda3/envs/MT_env/lib/python3.8/site-packages/torchvision/datasets/cifar.py", line 65, in __init__
    self.download()
  File "/home/takezawa/anaconda3/envs/MT_env/lib/python3.8/site-packages/torchvision/datasets/cifar.py", line 143, in download
    download_and_extract_archive(self.url, self.root, filename=self.filename, md5=self.tgz_md5)
  File "/home/takezawa/anaconda3/envs/MT_env/lib/python3.8/site-packages/torchvision/datasets/utils.py", line 316, in download_and_extract_archive
    download_url(url, download_root, filename, md5)
  File "/home/takezawa/anaconda3/envs/MT_env/lib/python3.8/site-packages/torchvision/datasets/utils.py", line 124, in download_url
    url = _get_redirect_url(url, max_hops=max_redirect_hops)
  File "/home/takezawa/anaconda3/envs/MT_env/lib/python3.8/site-packages/torchvision/datasets/utils.py", line 75, in _get_redirect_url
    with urllib.request.urlopen(urllib.request.Request(url, headers=headers)) as response:
  File "/home/takezawa/anaconda3/envs/MT_env/lib/python3.8/urllib/request.py", line 222, in urlopen
    return opener.open(url, data, timeout)
  File "/home/takezawa/anaconda3/envs/MT_env/lib/python3.8/urllib/request.py", line 525, in open
    response = self._open(req, data)
  File "/home/takezawa/anaconda3/envs/MT_env/lib/python3.8/urllib/request.py", line 542, in _open
    result = self._call_chain(self.handle_open, protocol, protocol +
  File "/home/takezawa/anaconda3/envs/MT_env/lib/python3.8/urllib/request.py", line 502, in _call_chain
    result = func(*args)
  File "/home/takezawa/anaconda3/envs/MT_env/lib/python3.8/urllib/request.py", line 1397, in https_open
    return self.do_open(http.client.HTTPSConnection, req,
  File "/home/takezawa/anaconda3/envs/MT_env/lib/python3.8/urllib/request.py", line 1357, in do_open
    raise URLError(err)
urllib.error.URLError: <urlopen error [Errno 101] Network is unreachable>
Traceback (most recent call last):
  File "/home/takezawa/anaconda3/envs/MT_env/lib/python3.8/urllib/request.py", line 1354, in do_open
    h.request(req.get_method(), req.selector, req.data, headers,
  File "/home/takezawa/anaconda3/envs/MT_env/lib/python3.8/http/client.py", line 1256, in request
    self._send_request(method, url, body, headers, encode_chunked)
  File "/home/takezawa/anaconda3/envs/MT_env/lib/python3.8/http/client.py", line 1302, in _send_request
    self.endheaders(body, encode_chunked=encode_chunked)
  File "/home/takezawa/anaconda3/envs/MT_env/lib/python3.8/http/client.py", line 1251, in endheaders
    self._send_output(message_body, encode_chunked=encode_chunked)
  File "/home/takezawa/anaconda3/envs/MT_env/lib/python3.8/http/client.py", line 1011, in _send_output
    self.send(msg)
  File "/home/takezawa/anaconda3/envs/MT_env/lib/python3.8/http/client.py", line 951, in send
    self.connect()
  File "/home/takezawa/anaconda3/envs/MT_env/lib/python3.8/http/client.py", line 1418, in connect
    super().connect()
  File "/home/takezawa/anaconda3/envs/MT_env/lib/python3.8/http/client.py", line 922, in connect
    self.sock = self._create_connection(
  File "/home/takezawa/anaconda3/envs/MT_env/lib/python3.8/socket.py", line 808, in create_connection
    raise err
  File "/home/takezawa/anaconda3/envs/MT_env/lib/python3.8/socket.py", line 796, in create_connection
    sock.connect(sa)
OSError: [Errno 101] Network is unreachable

During handling of the above exception, another exception occurred:

Traceback (most recent call last):
  File "main_vit.py", line 45, in <module>
    trainset = torchvision.datasets.CIFAR10(
  File "/home/takezawa/anaconda3/envs/MT_env/lib/python3.8/site-packages/torchvision/datasets/cifar.py", line 65, in __init__
    self.download()
  File "/home/takezawa/anaconda3/envs/MT_env/lib/python3.8/site-packages/torchvision/datasets/cifar.py", line 143, in download
    download_and_extract_archive(self.url, self.root, filename=self.filename, md5=self.tgz_md5)
  File "/home/takezawa/anaconda3/envs/MT_env/lib/python3.8/site-packages/torchvision/datasets/utils.py", line 316, in download_and_extract_archive
    download_url(url, download_root, filename, md5)
  File "/home/takezawa/anaconda3/envs/MT_env/lib/python3.8/site-packages/torchvision/datasets/utils.py", line 124, in download_url
    url = _get_redirect_url(url, max_hops=max_redirect_hops)
  File "/home/takezawa/anaconda3/envs/MT_env/lib/python3.8/site-packages/torchvision/datasets/utils.py", line 75, in _get_redirect_url
    with urllib.request.urlopen(urllib.request.Request(url, headers=headers)) as response:
  File "/home/takezawa/anaconda3/envs/MT_env/lib/python3.8/urllib/request.py", line 222, in urlopen
    return opener.open(url, data, timeout)
  File "/home/takezawa/anaconda3/envs/MT_env/lib/python3.8/urllib/request.py", line 525, in open
    response = self._open(req, data)
  File "/home/takezawa/anaconda3/envs/MT_env/lib/python3.8/urllib/request.py", line 542, in _open
    result = self._call_chain(self.handle_open, protocol, protocol +
  File "/home/takezawa/anaconda3/envs/MT_env/lib/python3.8/urllib/request.py", line 502, in _call_chain
    result = func(*args)
  File "/home/takezawa/anaconda3/envs/MT_env/lib/python3.8/urllib/request.py", line 1397, in https_open
    return self.do_open(http.client.HTTPSConnection, req,
  File "/home/takezawa/anaconda3/envs/MT_env/lib/python3.8/urllib/request.py", line 1357, in do_open
    raise URLError(err)
urllib.error.URLError: <urlopen error [Errno 101] Network is unreachable>
Traceback (most recent call last):
  File "/home/takezawa/anaconda3/envs/MT_env/lib/python3.8/urllib/request.py", line 1354, in do_open
    h.request(req.get_method(), req.selector, req.data, headers,
  File "/home/takezawa/anaconda3/envs/MT_env/lib/python3.8/http/client.py", line 1256, in request
    self._send_request(method, url, body, headers, encode_chunked)
  File "/home/takezawa/anaconda3/envs/MT_env/lib/python3.8/http/client.py", line 1302, in _send_request
    self.endheaders(body, encode_chunked=encode_chunked)
  File "/home/takezawa/anaconda3/envs/MT_env/lib/python3.8/http/client.py", line 1251, in endheaders
    self._send_output(message_body, encode_chunked=encode_chunked)
  File "/home/takezawa/anaconda3/envs/MT_env/lib/python3.8/http/client.py", line 1011, in _send_output
    self.send(msg)
  File "/home/takezawa/anaconda3/envs/MT_env/lib/python3.8/http/client.py", line 951, in send
    self.connect()
  File "/home/takezawa/anaconda3/envs/MT_env/lib/python3.8/http/client.py", line 1418, in connect
    super().connect()
  File "/home/takezawa/anaconda3/envs/MT_env/lib/python3.8/http/client.py", line 922, in connect
    self.sock = self._create_connection(
  File "/home/takezawa/anaconda3/envs/MT_env/lib/python3.8/socket.py", line 808, in create_connection
    raise err
  File "/home/takezawa/anaconda3/envs/MT_env/lib/python3.8/socket.py", line 796, in create_connection
    sock.connect(sa)
OSError: [Errno 101] Network is unreachable

During handling of the above exception, another exception occurred:

Traceback (most recent call last):
  File "main_vit.py", line 45, in <module>
    trainset = torchvision.datasets.CIFAR10(
  File "/home/takezawa/anaconda3/envs/MT_env/lib/python3.8/site-packages/torchvision/datasets/cifar.py", line 65, in __init__
    self.download()
  File "/home/takezawa/anaconda3/envs/MT_env/lib/python3.8/site-packages/torchvision/datasets/cifar.py", line 143, in download
    download_and_extract_archive(self.url, self.root, filename=self.filename, md5=self.tgz_md5)
  File "/home/takezawa/anaconda3/envs/MT_env/lib/python3.8/site-packages/torchvision/datasets/utils.py", line 316, in download_and_extract_archive
    download_url(url, download_root, filename, md5)
  File "/home/takezawa/anaconda3/envs/MT_env/lib/python3.8/site-packages/torchvision/datasets/utils.py", line 124, in download_url
    url = _get_redirect_url(url, max_hops=max_redirect_hops)
  File "/home/takezawa/anaconda3/envs/MT_env/lib/python3.8/site-packages/torchvision/datasets/utils.py", line 75, in _get_redirect_url
    with urllib.request.urlopen(urllib.request.Request(url, headers=headers)) as response:
  File "/home/takezawa/anaconda3/envs/MT_env/lib/python3.8/urllib/request.py", line 222, in urlopen
    return opener.open(url, data, timeout)
  File "/home/takezawa/anaconda3/envs/MT_env/lib/python3.8/urllib/request.py", line 525, in open
    response = self._open(req, data)
  File "/home/takezawa/anaconda3/envs/MT_env/lib/python3.8/urllib/request.py", line 542, in _open
    result = self._call_chain(self.handle_open, protocol, protocol +
  File "/home/takezawa/anaconda3/envs/MT_env/lib/python3.8/urllib/request.py", line 502, in _call_chain
    result = func(*args)
  File "/home/takezawa/anaconda3/envs/MT_env/lib/python3.8/urllib/request.py", line 1397, in https_open
    return self.do_open(http.client.HTTPSConnection, req,
  File "/home/takezawa/anaconda3/envs/MT_env/lib/python3.8/urllib/request.py", line 1357, in do_open
    raise URLError(err)
urllib.error.URLError: <urlopen error [Errno 101] Network is unreachable>
